2025-03-04 15:58:57,776 - INFO - Opened portal
2025-03-04 15:59:10,994 - INFO - Logged in
2025-03-04 15:59:11,005 - INFO - Got portal URL
2025-03-04 15:59:16,658 - INFO - Navigate to method called
2025-03-04 15:59:18,230 - INFO - Search and select report method called
2025-03-04 15:59:20,006 - INFO - Date report range method called
2025-03-04 15:59:20,238 - INFO - Run report method called
2025-03-04 16:02:38,396 - INFO - Opened portal
2025-03-04 16:02:55,405 - INFO - Logged in
2025-03-04 16:02:55,416 - INFO - Got portal URL
2025-03-04 16:03:02,348 - INFO - Navigate to method called
2025-03-04 16:03:04,261 - INFO - Search and select report method called
2025-03-04 16:03:06,209 - INFO - Date report range method called
2025-03-04 16:03:06,568 - INFO - Run report method called
2025-03-04 16:06:17,264 - INFO - Opened portal
2025-03-04 16:06:22,839 - INFO - Logged in
2025-03-04 16:06:22,852 - INFO - Got portal URL
2025-03-04 16:06:28,512 - INFO - Navigate to method called
2025-03-04 16:06:30,890 - INFO - Search and select report method called
2025-03-04 16:06:32,449 - INFO - Date report range method called
2025-03-04 16:06:34,946 - INFO - Run report method called
2025-03-04 16:09:12,213 - INFO - Opened portal
2025-03-04 16:09:23,282 - INFO - Logged in
2025-03-04 16:09:23,299 - INFO - Got portal URL
2025-03-04 16:09:28,296 - INFO - Navigate to method called
2025-03-04 16:09:30,298 - INFO - Search and select report method called
2025-03-04 16:09:31,768 - INFO - Date report range method called
2025-03-04 16:09:34,214 - INFO - Run report method called
2025-03-04 16:09:42,419 - INFO - Download report method called
2025-03-04 16:16:02,107 - INFO - Opened portal
2025-03-04 16:16:07,383 - INFO - Logged in
2025-03-04 16:16:07,404 - INFO - Got portal URL
2025-03-04 16:16:12,483 - INFO - Navigate to method called
2025-03-04 16:16:14,275 - INFO - Search and select report method called
2025-03-04 16:16:15,734 - INFO - Date report range method called
2025-03-04 16:16:18,176 - INFO - Run report method called
2025-03-04 16:16:36,242 - INFO - Download report method called
2025-03-04 16:16:56,903 - INFO - Opened portal
2025-03-04 16:17:02,210 - INFO - Logged in
2025-03-04 16:17:02,225 - INFO - Got portal URL
2025-03-04 16:17:07,274 - INFO - Navigate to method called
2025-03-04 16:17:09,156 - INFO - Search and select report method called
2025-03-04 16:17:10,617 - INFO - Date report range method called
2025-03-04 16:17:12,888 - INFO - Run report method called
2025-03-04 16:17:21,235 - INFO - Download report method called
2025-03-04 16:21:36,884 - INFO - Opened portal
2025-03-04 16:21:41,984 - INFO - Logged in
2025-03-04 16:21:41,994 - INFO - Got portal URL
2025-03-04 16:21:47,193 - INFO - Navigate to method called
2025-03-04 16:21:49,007 - INFO - Search and select report method called
2025-03-04 16:21:51,493 - INFO - Date report range method called
2025-03-04 16:21:54,014 - INFO - Run report method called
2025-03-04 16:22:04,275 - INFO - Download report method called
2025-03-04 16:22:28,317 - INFO - Opened portal
2025-03-04 16:22:33,851 - INFO - Logged in
2025-03-04 16:22:33,866 - INFO - Got portal URL
2025-03-04 16:22:38,543 - INFO - Navigate to method called
2025-03-04 16:22:40,411 - INFO - Search and select report method called
2025-03-04 16:22:41,898 - INFO - Date report range method called
2025-03-04 16:22:44,405 - INFO - Run report method called
2025-03-04 16:22:53,260 - INFO - Download report method called
2025-03-04 16:27:27,941 - INFO - Opened portal
2025-03-04 16:27:36,736 - INFO - Logged in
2025-03-04 16:27:36,749 - INFO - Got portal URL
2025-03-04 16:27:42,432 - INFO - Navigate to method called
2025-03-04 16:27:44,370 - INFO - Search and select report method called
2025-03-04 16:27:46,313 - INFO - Date report range method called
2025-03-04 16:27:48,655 - INFO - Run report method called
2025-03-04 16:27:53,441 - ERROR - Download directory does not exist: C:\Users\Niladri Mallik\Desktop\AFC_Automation\Report Downloads
2025-03-04 16:27:53,441 - INFO - 
2025-03-04 16:31:51,095 - INFO - Opened portal
2025-03-04 16:31:56,812 - INFO - Logged in
2025-03-04 16:31:56,819 - INFO - Got portal URL
2025-03-04 16:32:02,010 - INFO - Navigate to method called
2025-03-04 16:32:04,340 - INFO - Search and select report method called
2025-03-04 16:32:05,842 - INFO - Date report range method called
2025-03-04 16:32:08,548 - INFO - Run report method called
2025-03-04 16:32:16,709 - ERROR - Download directory does not exist: C:\Users\Niladri Mallik\Desktop\AFC_Automation\Report Downloads
2025-03-04 16:32:16,709 - INFO - 
2025-03-04 16:35:14,608 - INFO - Opened portal
2025-03-04 16:35:21,301 - INFO - Logged in
2025-03-04 16:35:21,314 - INFO - Got portal URL
2025-03-04 16:35:28,485 - INFO - Navigate to method called
2025-03-04 16:35:30,314 - INFO - Search and select report method called
2025-03-04 16:35:31,820 - INFO - Date report range method called
2025-03-04 16:35:34,290 - INFO - Run report method called
2025-03-04 16:35:45,004 - INFO - Download report method called
2025-03-04 17:18:27,654 - INFO - Opened portal
2025-03-04 17:18:41,889 - INFO - Logged in
2025-03-04 17:18:41,904 - INFO - Got portal URL
2025-03-04 17:18:44,734 - INFO - Error occurred: <class 'utils.exception_usage.SeleniumException'> Code: SEL_3_002 | Message : Error occurred while navigating to 'Reports'. | Contact: BI Automation Team - bi@graphxsys.com
2025-03-04 17:19:37,697 - INFO - Opened portal
2025-03-04 17:20:24,164 - INFO - Opened portal
2025-03-04 17:20:32,504 - INFO - Logged in
2025-03-04 17:20:32,515 - INFO - Got portal URL
2025-03-04 17:20:38,553 - INFO - Navigate to method called
2025-03-04 17:20:39,643 - INFO - Error occurred: SeleniumException Message : Unable to select report after search. | Contact: BI Automation Team - bi@graphxsys.com
2025-03-04 20:32:20,029 - ERROR - An unexpected error occured : 
Traceback (most recent call last):
  File "c:\Users\Prasad Goled\Desktop\Project\AFC_Automation\utils\experity_base.py", line 810, in logout
    logout_button = self.wait.until(EC.element_to_be_clickable((By.ID,'tdMenuBarItemlogout')))
  File "C:\Users\Prasad Goled\Desktop\Project\AFC_Automation\venv\lib\site-packages\selenium\webdriver\support\wait.py", line 137, in until
    value = method(self._driver)
  File "C:\Users\Prasad Goled\Desktop\Project\AFC_Automation\venv\lib\site-packages\selenium\webdriver\support\expected_conditions.py", line 631, in _predicate
    target = driver.find_element(*target)  # grab element at locator
  File "C:\Users\Prasad Goled\Desktop\Project\AFC_Automation\venv\lib\site-packages\selenium\webdriver\remote\webdriver.py", line 898, in find_element
    return self.execute(Command.FIND_ELEMENT, {"using": by, "value": value})["value"]
  File "C:\Users\Prasad Goled\Desktop\Project\AFC_Automation\venv\lib\site-packages\selenium\webdriver\remote\webdriver.py", line 429, in execute
    self.error_handler.check_response(response)
  File "C:\Users\Prasad Goled\Desktop\Project\AFC_Automation\venv\lib\site-packages\selenium\webdriver\remote\errorhandler.py", line 232, in check_response
    raise exception_class(message, screen, stacktrace)
selenium.common.exceptions.InvalidSessionIdException: Message: invalid session id: session deleted as the browser has closed the connection
from disconnected: not connected to DevTools
  (Session info: chrome=133.0.6943.142)
Stacktrace:
	GetHandleVerifier [0x00007FF7EDFAC6A5+28789]
	(No symbol) [0x00007FF7EDF15B20]
	(No symbol) [0x00007FF7EDDA8F9A]
	(No symbol) [0x00007FF7EDD94D75]
	(No symbol) [0x00007FF7EDDB9784]
	(No symbol) [0x00007FF7EDE2F0BF]
	(No symbol) [0x00007FF7EDE4F0D2]
	(No symbol) [0x00007FF7EDE27103]
	(No symbol) [0x00007FF7EDDEFFC0]
	(No symbol) [0x00007FF7EDDF1273]
	GetHandleVerifier [0x00007FF7EE2F1AED+3458237]
	GetHandleVerifier [0x00007FF7EE30829C+3550316]
	GetHandleVerifier [0x00007FF7EE2FDB9D+3507565]
	GetHandleVerifier [0x00007FF7EE072C6A+841274]
	(No symbol) [0x00007FF7EDF209EF]
	(No symbol) [0x00007FF7EDF1CB34]
	(No symbol) [0x00007FF7EDF1CCD6]
	(No symbol) [0x00007FF7EDF0C119]
	BaseThreadInitThunk [0x00007FFA1475259D+29]
	RtlUserThreadStart [0x00007FFA15F6AF38+40]


During handling of the above exception, another exception occurred:

Traceback (most recent call last):
  File "c:\Users\Prasad Goled\Desktop\Project\AFC_Automation\utils\main_new.py", line 56, in <module>
    experity.logout()
  File "c:\Users\Prasad Goled\Desktop\Project\AFC_Automation\utils\experity_base.py", line 815, in logout
    raise SeleniumException(f"Code: {em.LOGOUT_ISSUE} | Message : Error occurred during logout.")
utils.exception_usage.SeleniumException: Code: EXP_1_002 | Message : Error occurred during logout. | Contact: BI Automation Team - bi@graphxsys.com

2025-03-04 20:38:11,681 - ERROR - An unexpected error occured : 
Traceback (most recent call last):
  File "c:\Users\Prasad Goled\Desktop\Project\AFC_Automation\utils\experity_base.py", line 183, in login
    self.driver.find_element(By.ID, "txtPassword").save_screenshot(f"Screenshots/Password_Expire_{username}_{TIMESTAMP_IDENTIFIER}.png")
AttributeError: 'WebElement' object has no attribute 'save_screenshot'

During handling of the above exception, another exception occurred:

Traceback (most recent call last):
  File "c:\Users\Prasad Goled\Desktop\Project\AFC_Automation\utils\main_new.py", line 32, in <module>
    experity.login(username, password)
  File "c:\Users\Prasad Goled\Desktop\Project\AFC_Automation\utils\experity_base.py", line 192, in login
    raise SeleniumException(f"Code: {em.INVALID_CREDENTIALS} | Message : Error in Logging process")
utils.exception_usage.SeleniumException: Code: EXP_1 | Message : Error in Logging process | Contact: BI Automation Team - bi@graphxsys.com

2025-03-04 21:13:47,225 - ERROR - Invalid user credentials. Please check username and password.
2025-03-04 22:15:32,437 - ERROR - Invalid user credentials. Please check username and password.
2025-03-04 22:15:45,832 - ERROR - An unexpected error occured : 
Traceback (most recent call last):
  File "c:\Users\Prasad Goled\Desktop\Project\AFC_Automation\utils\main_new.py", line 34, in <module>
    experity.select_pm_report('Financials', 'Revenue', 'REV 14')
  File "c:\Users\Prasad Goled\Desktop\Project\AFC_Automation\utils\experity_base.py", line 61, in wrapper
    raise SeleniumException(f"Message : {func.__name__} failed after {retries} retries.")
utils.exception_usage.SeleniumException: Message : select_pm_report failed after 3 retries. | Contact: BI Automation Team - bi@graphxsys.com

2025-03-05 16:10:53,497 - ERROR - Invalid user credentials. Please check username and password.
2025-03-05 16:11:34,066 - ERROR - An unexpected error occured : 
Traceback (most recent call last):
  File "c:\Users\Prasad Goled\Desktop\Project\AFC_Automation\main_new.py", line 104, in <module>
    experity.select_pm_report('Financials', 'Adjustments', 'ADJ 0')
  File "c:\Users\Prasad Goled\Desktop\Project\AFC_Automation\utils\experity_base.py", line 61, in wrapper
    raise SeleniumException(f"Message : {func.__name__} failed after {retries} retries.")
utils.exception_usage.SeleniumException: Message : select_pm_report failed after 3 retries. | Contact: BI Automation Team - bi@graphxsys.com

2025-03-05 16:13:31,259 - ERROR - Invalid user credentials. Please check username and password.
2025-03-05 16:13:31,428 - ERROR - An unexpected error occured : 
Traceback (most recent call last):
  File "c:\Users\Prasad Goled\Desktop\Project\AFC_Automation\utils\experity_base.py", line 190, in login
    raise Exception("Invalid user credentials.")
Exception: Invalid user credentials.

During handling of the above exception, another exception occurred:

Traceback (most recent call last):
  File "c:\Users\Prasad Goled\Desktop\Project\AFC_Automation\main_new.py", line 100, in <module>
    experity.login(username, password)
  File "c:\Users\Prasad Goled\Desktop\Project\AFC_Automation\utils\experity_base.py", line 214, in login
    raise SeleniumException(f"Code: {em.INVALID_CREDENTIALS} | Message : Error in Logging process")
utils.exception_usage.SeleniumException: Code: EXP_1 | Message : Error in Logging process | Contact: BI Automation Team - bi@graphxsys.com

2025-03-05 16:32:59,679 - ERROR - An unexpected error occured : 
Traceback (most recent call last):
  File "c:\Users\Prasad Goled\Desktop\Project\AFC_Automation\utils\experity_base.py", line 188, in login
    raise Exception("Invalid user credentials.")
Exception: Invalid user credentials.

During handling of the above exception, another exception occurred:

Traceback (most recent call last):
  File "c:\Users\Prasad Goled\Desktop\Project\AFC_Automation\main_new.py", line 100, in <module>
    experity.login(username, password)
  File "c:\Users\Prasad Goled\Desktop\Project\AFC_Automation\utils\experity_base.py", line 210, in login
    raise SeleniumException(f"Code: {em.INVALID_CREDENTIALS} | Message : Error in Logging process - {str(e)}")
utils.exception_usage.SeleniumException: Code: EXP_1 | Message : Error in Logging process - Invalid user credentials. | Contact: BI Automation Team - bi@graphxsys.com

2025-03-05 17:01:00,407 - ERROR - An unexpected error occured : 
Traceback (most recent call last):
  File "c:\Users\Prasad Goled\Desktop\Project\AFC_Automation\utils\experity_base.py", line 188, in login
    raise Exception("Invalid user credentials.")
Exception: Invalid user credentials.

During handling of the above exception, another exception occurred:

Traceback (most recent call last):
  File "c:\Users\Prasad Goled\Desktop\Project\AFC_Automation\main_new.py", line 100, in <module>
    experity.login(username, password)
  File "c:\Users\Prasad Goled\Desktop\Project\AFC_Automation\utils\experity_base.py", line 210, in login
    raise SeleniumException(f"Code: {em.INVALID_CREDENTIALS} | Message : Error in Logging process - {str(e)}")
utils.exception_usage.SeleniumException: Code: EXP_1 | Message : Error in Logging process - Invalid user credentials. | Contact: BI Automation Team - bi@graphxsys.com

2025-03-05 22:00:29,982 - ERROR - An unexpected error occured : 
Traceback (most recent call last):
  File "c:\Users\Prasad Goled\Desktop\Project\AFC_Automation\utils\experity_base.py", line 188, in login
    raise Exception("Invalid user credentials.")
Exception: Invalid user credentials.

During handling of the above exception, another exception occurred:

Traceback (most recent call last):
  File "c:\Users\Prasad Goled\Desktop\Project\AFC_Automation\main_new.py", line 100, in <module>
    experity.login(username, password)
  File "c:\Users\Prasad Goled\Desktop\Project\AFC_Automation\utils\experity_base.py", line 210, in login
    raise SeleniumException(f"Code: {em.INVALID_CREDENTIALS} | Message : Error in Logging process - {str(e)}")
utils.exception_usage.SeleniumException: Code: EXP_1 | Message : Error in Logging process - Invalid user credentials. | Contact: BI Automation Team - bi@graphxsys.com

